<?xml version="1.0" encoding="utf-8"?>
<!-- This URDF was automatically created by SolidWorks to URDF Exporter! Originally created by Stephen Brawner (brawner@gmail.com) 
     Commit Version: 1.6.0-4-g7f85cfe  Build Version: 1.6.7995.38578
     For more information, please see http://wiki.ros.org/sw_urdf_exporter -->
<robot
  name="leg_urdf20250414_1">
  <link
    name="base">
    <inertial>
      <origin
        xyz="-0.0066699 -0.0036748 -0.0047946"
        rpy="0 0 0" />
      <mass
        value="5.3832" />
      <inertia
        ixx="0.013437"
        ixy="-6.9871E-06"
        ixz="-0.00020711"
        iyy="0.031665"
        iyz="-9.5328E-06"
        izz="0.039598" />
    </inertial>
    <visual>
      <origin
        xyz="0 0 0"
        rpy="0 0 0" />
      <geometry>
        <mesh
          filename="package://leg_urdf20250414_1/meshes/base.STL" />
      </geometry>
      <material
        name="">
        <color
          rgba="0.25098 0.25098 0.25098 1" />
      </material>
    </visual>
    <collision>
      <origin
        xyz="0 0 0"
        rpy="0 0 0" />
      <geometry>
        <mesh
          filename="package://leg_urdf20250414_1/meshes/base.STL" />
      </geometry>
    </collision>
  </link>
  <link
    name="LF_hip">
    <inertial>
      <origin
        xyz="0.042864 -0.00047394 -2.8926E-05"
        rpy="0 0 0" />
      <mass
        value="0.16386" />
      <inertia
        ixx="0.00012341"
        ixy="-5.2157E-06"
        ixz="-1.1555E-06"
        iyy="0.0001958"
        iyz="-9.8907E-08"
        izz="0.00010494" />
    </inertial>
    <visual>
      <origin
        xyz="0 0 0"
        rpy="0 0 0" />
      <geometry>
        <mesh
          filename="package://leg_urdf20250414_1/meshes/LF_hip.STL" />
      </geometry>
      <material
        name="">
        <color
          rgba="0.89804 0.91765 0.92941 1" />
      </material>
    </visual>
    <collision>
      <origin
        xyz="0 0 0"
        rpy="0 0 0" />
      <geometry>
        <mesh
          filename="package://leg_urdf20250414_1/meshes/LF_hip.STL" />
      </geometry>
    </collision>
  </link>
  <joint
    name="LF_HAA"
    type="revolute">
    <origin
      xyz="0.1978 0.06 -0.0073383"
      rpy="0 0 0" />
    <parent
      link="base" />
    <child
      link="LF_hip" />
    <axis
      xyz="1 0 0" />
    <limit
      lower="-1.05"
      upper="1.05"
      effort="60"
      velocity="15" />
  </joint>
  <link
    name="LF_thigh">
    <inertial>
      <origin
        xyz="0.00436683720793934 0.0220762223078676 -0.0940952641066127"
        rpy="0 0 0" />
      <mass
        value="0.882649526971419" />
      <inertia
        ixx="0.00415924322538449"
        ixy="-5.34750962434057E-06"
        ixz="-9.05829574075116E-05"
        iyy="0.00457431590966923"
        iyz="3.5094545931096E-05"
        izz="0.000520630016824553" />
    </inertial>
    <visual>
      <origin
        xyz="0 0 0"
        rpy="0 0 0" />
      <geometry>
        <mesh
          filename="package://leg_urdf20250414_1/meshes/LF_thigh.STL" />
      </geometry>
      <material
        name="">
        <color
          rgba="0.898039215686275 0.917647058823529 0.929411764705882 1" />
      </material>
    </visual>
    <collision>
      <origin
        xyz="0 0 0"
        rpy="0 0 0" />
      <geometry>
        <mesh
          filename="package://leg_urdf20250414_1/meshes/LF_thigh.STL" />
      </geometry>
    </collision>
  </link>
  <joint
    name="LF_HFE"
    type="revolute">
    <origin
      xyz="0.0627 0.0624 0"
      rpy="0 0 0" />
    <parent
      link="LF_hip" />
    <child
      link="LF_thigh" />
    <axis
      xyz="0 1 0" />
    <limit
      lower="-1.57"
      upper="3.35"
      effort="60"
      velocity="15" />
  </joint>
  <link
    name="LF_calf">
    <inertial>
      <origin
        xyz="0.0353231393749997 0.000329711873662181 0.137279161740425"
        rpy="0 0 0" />
      <mass
        value="0.291228893559729" />
      <inertia
        ixx="0.00107142137463083"
        ixy="8.16218987771121E-08"
        ixz="-0.000225822383336276"
        iyy="0.0011429950874814"
        iyz="1.42384757266927E-07"
        izz="8.3967835261648E-05" />
    </inertial>
    <visual>
      <origin
        xyz="0 0 0"
        rpy="0 0 0" />
      <geometry>
        <mesh
          filename="package://leg_urdf20250414_1/meshes/LF_calf.STL" />
      </geometry>
      <material
        name="">
        <color
          rgba="1 1 1 1" />
      </material>
    </visual>
    <collision>
      <origin
        xyz="0 0 0"
        rpy="0 0 0" />
      <geometry>
        <mesh
          filename="package://leg_urdf20250414_1/meshes/LF_calf.STL" />
      </geometry>
    </collision>
  </link>
  <joint
    name="LF_KFE"
    type="revolute">
    <origin
      xyz="0.024642 0.033 -0.28146"
      rpy="0 0 0" />
    <parent
      link="LF_thigh" />
    <child
      link="LF_calf" />
    <axis
      xyz="0 1 0" />
    <limit
      lower="0"
      upper="2.2"
      effort="60"
      velocity="15" />
  </joint>
  <link
    name="LF_FOOT">
    <inertial>
      <origin
        xyz="-0.609114064249484 0.332622028991796 -0.155700005966804"
        rpy="0 0 0" />
      <mass
        value="0.0259775757821095" />
      <inertia
        ixx="5.12957211624476E-06"
        ixy="-1.23448279124937E-06"
        ixz="-1.64037105362469E-12"
        iyy="2.66954930549516E-06"
        iyz="1.55483362744839E-12"
        izz="6.06492352296267E-06" />
    </inertial>
    <visual>
      <origin
        xyz="0 0 0"
        rpy="0 0 0" />
      <geometry>
        <mesh
          filename="package://leg_urdf20250414_1/meshes/LF_FOOT.STL" />
      </geometry>
      <material
        name="">
        <color
          rgba="0.384313725490196 0.384313725490196 0.384313725490196 1" />
      </material>
    </visual>
    <collision>
      <origin
        xyz="0 0 0"
        rpy="0 0 0" />
      <geometry>
        <mesh
          filename="package://leg_urdf20250414_1/meshes/LF_FOOT.STL" />
      </geometry>
    </collision>
  </link>
  <joint
    name="LF_foot_fixed"
    type="fixed">
    <origin
      xyz="-0.285141510567482 -0.155399999999991 -0.318544612097913"
      rpy="-1.5707963267949 1.52191034425173 3.14159265358979" />
    <parent
      link="LF_calf" />
    <child
      link="LF_FOOT" />
    <axis
      xyz="0 0 0" />
    <limit
      lower="-2.72"
      upper="-0.84"
      effort="60"
      velocity="15" />
  </joint>
  <link
    name="LH_hip">
    <inertial>
      <origin
        xyz="-0.0433644646355627 -0.000473926080253394 2.89141840380536E-05"
        rpy="0 0 0" />
      <mass
        value="0.16385534253276" />
      <inertia
        ixx="0.000123407065871323"
        ixy="5.21572443490012E-06"
        ixz="-1.15546077533709E-06"
        iyy="0.000195800284945129"
        iyz="9.8908641401561E-08"
        izz="0.000104939607045861" />
    </inertial>
    <visual>
      <origin
        xyz="0 0 0"
        rpy="0 0 0" />
      <geometry>
        <mesh
          filename="package://leg_urdf20250414_1/meshes/LH_hip.STL" />
      </geometry>
      <material
        name="">
        <color
          rgba="0.898039215686275 0.917647058823529 0.929411764705882 1" />
      </material>
    </visual>
    <collision>
      <origin
        xyz="0 0 0"
        rpy="0 0 0" />
      <geometry>
        <mesh
          filename="package://leg_urdf20250414_1/meshes/LH_hip.STL" />
      </geometry>
    </collision>
  </link>
  <joint
    name="LH_HAA"
    type="revolute">
    <origin
      xyz="-0.1973 0.06 -0.0073383"
      rpy="0 0 0" />
    <parent
      link="base" />
    <child
      link="LH_hip" />
    <axis
      xyz="-1 0 0" />
    <limit
      lower="-1.05"
      upper="1.05"
      effort="60"
      velocity="15" />
  </joint>
  <link
    name="LH_thigh">
    <inertial>
      <origin
        xyz="0.00698095866463322 0.0650895806226572 -0.0944113989514764"
        rpy="0 0 0" />
      <mass
        value="0.878447120767621" />
      <inertia
        ixx="0.00416751500567482"
        ixy="-5.43143322040717E-06"
        ixz="-0.00018081047075565"
        iyy="0.00457417825946368"
        iyz="3.50855269071827E-05"
        izz="0.00051219180647571" />
    </inertial>
    <visual>
      <origin
        xyz="0 0 0"
        rpy="0 0 0" />
      <geometry>
        <mesh
          filename="package://leg_urdf20250414_1/meshes/LH_thigh.STL" />
      </geometry>
      <material
        name="">
        <color
          rgba="0.898039215686275 0.917647058823529 0.929411764705882 1" />
      </material>
    </visual>
    <collision>
      <origin
        xyz="0 0 0"
        rpy="0 0 0" />
      <geometry>
        <mesh
          filename="package://leg_urdf20250414_1/meshes/LH_thigh.STL" />
      </geometry>
    </collision>
  </link>
  <joint
    name="LH_HFE"
    type="revolute">
    <origin
      xyz="-0.0632 0.0195 0"
      rpy="0 0 0" />
    <parent
      link="LH_hip" />
    <child
      link="LH_thigh" />
    <axis
      xyz="0 1 0" />
    <limit
      lower="-1.57"
      upper="3.35"
      effort="60"
      velocity="15" />
  </joint>
  <link
    name="LH_calf">
    <inertial>
      <origin
        xyz="0.0353231351553344 0.000329711798349563 0.137279148280852"
        rpy="0 0 0" />
      <mass
        value="0.29122892183166" />
      <inertia
        ixx="0.00107142142787039"
        ixy="8.16212025763138E-08"
        ixz="-0.000225822393349355"
        iyy="0.00114299514793146"
        iyz="1.42387332405903E-07"
        izz="8.39678431642949E-05" />
    </inertial>
    <visual>
      <origin
        xyz="0 0 0"
        rpy="0 0 0" />
      <geometry>
        <mesh
          filename="package://leg_urdf20250414_1/meshes/LH_calf.STL" />
      </geometry>
      <material
        name="">
        <color
          rgba="1 1 1 1" />
      </material>
    </visual>
    <collision>
      <origin
        xyz="0 0 0"
        rpy="0 0 0" />
      <geometry>
        <mesh
          filename="package://leg_urdf20250414_1/meshes/LH_calf.STL" />
      </geometry>
    </collision>
  </link>
  <joint
    name="LH_KFE"
    type="revolute">
    <origin
      xyz="0.025437 0.0759 -0.28147"
      rpy="0 0 0" />
    <parent
      link="LH_thigh" />
    <child
      link="LH_calf" />
    <axis
      xyz="0 1 0" />
    <limit
      lower="0"
      upper="2.2"
      effort="60"
      velocity="15" />
  </joint>
  <link
    name="LH_FOOT">
    <inertial>
      <origin
        xyz="-0.583678557893057 -0.186960008792956 -0.155700005966238"
        rpy="0 0 0" />
      <mass
        value="0.0259775757821097" />
      <inertia
        ixx="5.12957211624476E-06"
        ixy="-1.23448279124939E-06"
        ixz="-1.64037100818952E-12"
        iyy="2.66954930549518E-06"
        iyz="1.55483370143718E-12"
        izz="6.0649235229627E-06" />
    </inertial>
    <visual>
      <origin
        xyz="0 0 0"
        rpy="0 0 0" />
      <geometry>
        <mesh
          filename="package://leg_urdf20250414_1/meshes/LH_FOOT.STL" />
      </geometry>
      <material
        name="">
        <color
          rgba="0.384313725490196 0.384313725490196 0.384313725490196 1" />
      </material>
    </visual>
    <collision>
      <origin
        xyz="0 0 0"
        rpy="0 0 0" />
      <geometry>
        <mesh
          filename="package://leg_urdf20250414_1/meshes/LH_FOOT.STL" />
      </geometry>
    </collision>
  </link>
  <joint
    name="LH_foot_fixed"
    type="fixed">
    <origin
      xyz="0.235062736575495 -0.1554 -0.318529655609828"
      rpy="-1.5707963267949 1.52191034425174 3.14159265358979" />
    <parent
      link="LH_calf" />
    <child
      link="LH_FOOT" />
    <axis
      xyz="0 0 0" />
    <limit
      lower="-2.72"
      upper="-0.84"
      effort="60"
      velocity="15" />
  </joint>
  <link
    name="RF_hip">
    <inertial>
      <origin
        xyz="0.0433644648693298 0.0004739479629823 -2.89217444162659E-05"
        rpy="0 0 0" />
      <mass
        value="0.163855386935685" />
      <inertia
        ixx="0.000123407074924426"
        ixy="5.21571674467525E-06"
        ixz="-1.15545094341875E-06"
        iyy="0.000195800300641504"
        iyz="9.89103694234527E-08"
        izz="0.000104939625038023" />
    </inertial>
    <visual>
      <origin
        xyz="0 0 0"
        rpy="0 0 0" />
      <geometry>
        <mesh
          filename="package://leg_urdf20250414_1/meshes/RF_hip.STL" />
      </geometry>
      <material
        name="">
        <color
          rgba="0.898039215686275 0.917647058823529 0.929411764705882 1" />
      </material>
    </visual>
    <collision>
      <origin
        xyz="0 0 0"
        rpy="0 0 0" />
      <geometry>
        <mesh
          filename="package://leg_urdf20250414_1/meshes/RF_hip.STL" />
      </geometry>
    </collision>
  </link>
  <joint
    name="RF_HAA"
    type="revolute">
    <origin
      xyz="0.1973 -0.06 -0.0073383"
      rpy="0 0 0" />
    <parent
      link="base" />
    <child
      link="RF_hip" />
    <axis
      xyz="1 0 0" />
    <limit
      lower="-1.05"
      upper="1.05"
      effort="60"
      velocity="15" />
  </joint>
  <link
    name="RF_thigh">
    <inertial>
      <origin
        xyz="0.00450532741981985 -0.0651233509730109 -0.0943309028284363"
        rpy="0 0 0" />
      <mass
        value="0.880353408720973" />
      <inertia
        ixx="0.00415842883045724"
        ixy="5.34875598523864E-06"
        ixz="-9.05011725768449E-05"
        iyy="0.0045734761437616"
        iyz="-3.50630935382061E-05"
        izz="0.000520561613293802" />
    </inertial>
    <visual>
      <origin
        xyz="0 0 0"
        rpy="0 0 0" />
      <geometry>
        <mesh
          filename="package://leg_urdf20250414_1/meshes/RF_thigh.STL" />
      </geometry>
      <material
        name="">
        <color
          rgba="0.898039215686275 0.917647058823529 0.929411764705882 1" />
      </material>
    </visual>
    <collision>
      <origin
        xyz="0 0 0"
        rpy="0 0 0" />
      <geometry>
        <mesh
          filename="package://leg_urdf20250414_1/meshes/RF_thigh.STL" />
      </geometry>
    </collision>
  </link>
  <joint
    name="RF_HFE"
    type="revolute">
    <origin
      xyz="0.0632 -0.0195 0"
      rpy="0 0 0" />
    <parent
      link="RF_hip" />
    <child
      link="RF_thigh" />
    <axis
      xyz="0 -1 0" />
    <limit
      lower="-3.35"
      upper="1.57"
      effort="60"
      velocity="15" />
  </joint>
  <link
    name="RF_calf">
    <inertial>
      <origin
        xyz="0.0353226630049198 -0.000330081314130204 0.137276291361542"
        rpy="0 0 0" />
      <mass
        value="0.291237111817664" />
      <inertia
        ixx="0.00107148301804938"
        ixy="-8.25716094186912E-08"
        ixz="-0.000225830862552133"
        iyy="0.00114305842409935"
        iyz="-1.42952371989528E-07"
        izz="8.39698788065223E-05" />
    </inertial>
    <visual>
      <origin
        xyz="0 0 0"
        rpy="0 0 0" />
      <geometry>
        <mesh
          filename="package://leg_urdf20250414_1/meshes/RF_calf.STL" />
      </geometry>
      <material
        name="">
        <color
          rgba="1 1 1 1" />
      </material>
    </visual>
    <collision>
      <origin
        xyz="0 0 0"
        rpy="0 0 0" />
      <geometry>
        <mesh
          filename="package://leg_urdf20250414_1/meshes/RF_calf.STL" />
      </geometry>
    </collision>
  </link>
  <joint
    name="RF_KFE"
    type="revolute">
    <origin
      xyz="0.024642 -0.0759 -0.28146"
      rpy="0 0 0" />
    <parent
      link="RF_thigh" />
    <child
      link="RF_calf" />
    <axis
      xyz="0 -1 0" />
    <limit
      lower="-2.2"
      upper="0"
      effort="60"
      velocity="15" />
  </joint>
  <link
    name="RF_FOOT">
    <inertial>
      <origin
        xyz="-0.609114102277992 0.332621951902891 0.155699976456909"
        rpy="0 0 0" />
      <mass
        value="0.0259777190681024" />
      <inertia
        ixx="5.12961013777177E-06"
        ixy="-1.23449156481814E-06"
        ixz="-4.24107873171126E-12"
        iyy="2.66955581065844E-06"
        iyz="4.26735761284004E-12"
        izz="6.06496341868077E-06" />
    </inertial>
    <visual>
      <origin
        xyz="0 0 0"
        rpy="0 0 0" />
      <geometry>
        <mesh
          filename="package://leg_urdf20250414_1/meshes/RF_FOOT.STL" />
      </geometry>
      <material
        name="">
        <color
          rgba="0.384313725490196 0.384313725490196 0.384313725490196 1" />
      </material>
    </visual>
    <collision>
      <origin
        xyz="0 0 0"
        rpy="0 0 0" />
      <geometry>
        <mesh
          filename="package://leg_urdf20250414_1/meshes/RF_FOOT.STL" />
      </geometry>
    </collision>
  </link>
  <joint
    name="RF_foot_fixed"
    type="fixed">
    <origin
      xyz="-0.285141510567482 0.15539999999999 -0.318544612097913"
      rpy="-1.57079632679489 1.5219103349388 3.14159265358979" />
    <parent
      link="RF_calf" />
    <child
      link="RF_FOOT" />
    <axis
      xyz="0 0 0" />
  </joint>
  <link
    name="RH_hip">
    <inertial>
      <origin
        xyz="-0.0249543538828536 0.000473931035222447 2.89098388941422E-05"
        rpy="0 0 0" />
      <mass
        value="0.163855386935684" />
      <inertia
        ixx="0.000123407074915557"
        ixy="-5.21572449377728E-06"
        ixz="-1.15545638185312E-06"
        iyy="0.000195800305834264"
        iyz="-9.891217026839E-08"
        izz="0.000104939619827479" />
    </inertial>
    <visual>
      <origin
        xyz="0 0 0"
        rpy="0 0 0" />
      <geometry>
        <mesh
          filename="package://leg_urdf20250414_1/meshes/RH_hip.STL" />
      </geometry>
      <material
        name="">
        <color
          rgba="0.792156862745098 0.819607843137255 0.933333333333333 1" />
      </material>
    </visual>
    <collision>
      <origin
        xyz="0 0 0"
        rpy="0 0 0" />
      <geometry>
        <mesh
          filename="package://leg_urdf20250414_1/meshes/RH_hip.STL" />
      </geometry>
    </collision>
  </link>
  <joint
    name="RH_HAA"
    type="revolute">
    <origin
      xyz="-0.21571 -0.06 -0.0073383"
      rpy="0 0 0" />
    <parent
      link="base" />
    <child
      link="RH_hip" />
    <axis
      xyz="-1 0 0" />
    <limit
      lower="-1.05"
      upper="1.05"
      effort="60"
      velocity="15" />
  </joint>
  <link
    name="RH_thigh">
    <inertial>
      <origin
        xyz="0.00710534427929871 -0.0466324566370045 -0.0962519426438375"
        rpy="0 0 0" />
      <mass
        value="0.882603535541175" />
      <inertia
        ixx="0.00416687973544053"
        ixy="5.43296791673738E-06"
        ixz="-0.00018072681332933"
        iyy="0.00457355632460905"
        iyz="-3.50529337456979E-05"
        izz="0.000512220342872574" />
    </inertial>
    <visual>
      <origin
        xyz="0 0 0"
        rpy="0 0 0" />
      <geometry>
        <mesh
          filename="package://leg_urdf20250414_1/meshes/RH_thigh.STL" />
      </geometry>
      <material
        name="">
        <color
          rgba="0.898039215686275 0.917647058823529 0.929411764705882 1" />
      </material>
    </visual>
    <collision>
      <origin
        xyz="0 0 0"
        rpy="0 0 0" />
      <geometry>
        <mesh
          filename="package://leg_urdf20250414_1/meshes/RH_thigh.STL" />
      </geometry>
    </collision>
  </link>
  <joint
    name="RH_HFE"
    type="revolute">
    <origin
      xyz="-0.04479 -0.037843 0.0022486"
      rpy="0 0 0" />
    <parent
      link="RH_hip" />
    <child
      link="RH_thigh" />
    <axis
      xyz="0 -1 0" />
    <limit
      lower="-3.35"
      upper="1.57"
      effort="60"
      velocity="15" />
  </joint>
  <link
    name="RH_calf">
    <inertial>
      <origin
        xyz="0.0353226646106752 -0.000330081486733247 0.137276294734896"
        rpy="0 0 0" />
      <mass
        value="0.291237107924892" />
      <inertia
        ixx="0.0010714830667072"
        ixy="-8.25724537206379E-08"
        ixz="-0.000225830869900819"
        iyy="0.00114305847107113"
        iyz="-1.42955155261649E-07"
        izz="8.39698773791045E-05" />
    </inertial>
    <visual>
      <origin
        xyz="0 0 0"
        rpy="0 0 0" />
      <geometry>
        <mesh
          filename="package://leg_urdf20250414_1/meshes/RH_calf.STL" />
      </geometry>
      <material
        name="">
        <color
          rgba="1 1 1 1" />
      </material>
    </visual>
    <collision>
      <origin
        xyz="0 0 0"
        rpy="0 0 0" />
      <geometry>
        <mesh
          filename="package://leg_urdf20250414_1/meshes/RH_calf.STL" />
      </geometry>
    </collision>
  </link>
  <joint
    name="RH_KFE"
    type="revolute">
    <origin
      xyz="0.025437 -0.057557 -0.28372"
      rpy="0 0 0" />
    <parent
      link="RH_thigh" />
    <child
      link="RH_calf" />
    <axis
      xyz="0 -1 0" />
    <limit
      lower="-2.2"
      upper="0"
      effort="60"
      velocity="15" />
  </joint>
  <link
    name="RH_FOOT">
    <inertial>
      <origin
        xyz="-0.583678593178597 -0.18696007910181 0.155699976457479"
        rpy="0 0 0" />
      <mass
        value="0.0259777190681019" />
      <inertia
        ixx="5.12961011009384E-06"
        ixy="-1.23449159239591E-06"
        ixz="-4.24107872388451E-12"
        iyy="2.66955583833627E-06"
        iyz="4.26735761111812E-12"
        izz="6.06496341868067E-06" />
    </inertial>
    <visual>
      <origin
        xyz="0 0 0"
        rpy="0 0 0" />
      <geometry>
        <mesh
          filename="package://leg_urdf20250414_1/meshes/RH_FOOT.STL" />
      </geometry>
      <material
        name="">
        <color
          rgba="0.384313725490196 0.384313725490196 0.384313725490196 1" />
      </material>
    </visual>
    <collision>
      <origin
        xyz="0 0 0"
        rpy="0 0 0" />
      <geometry>
        <mesh
          filename="package://leg_urdf20250414_1/meshes/RH_FOOT.STL" />
      </geometry>
    </collision>
  </link>
  <joint
    name="RH_foot_fixed"
    type="fixed">
    <origin
      xyz="0.23506273675208 0.155400000000001 -0.318529655493733"
      rpy="-1.5707963267949 1.52191034614904 3.14159265358979" />
    <parent
      link="RH_calf" />
    <child
      link="RH_FOOT" />
    <axis
      xyz="0 0 0" />
  </joint>
  <link
    name="base_imu">
    <inertial>
      <origin
        xyz="-0.140227009525555 0.0236612413246912 0.0203176869868776"
        rpy="0 0 0" />
      <mass
        value="15.8318733004591" />
      <inertia
        ixx="0.25571851283607"
        ixy="0.00106802564790356"
        ixz="0.00465265089929087"
        iyy="0.880336400358266"
        iyz="-0.0114555500717523"
        izz="0.92731266552924" />
    </inertial>
    <visual>
      <origin
        xyz="0 0 0"
        rpy="0 0 0" />
      <geometry>
        <mesh
          filename="package://leg_urdf20250414_1/meshes/base_imu.STL" />
      </geometry>
      <material
        name="">
        <color
          rgba="1 1 1 1" />
      </material>
    </visual>
    <collision>
      <origin
        xyz="0 0 0"
        rpy="0 0 0" />
      <geometry>
        <mesh
          filename="package://leg_urdf20250414_1/meshes/base_imu.STL" />
      </geometry>
    </collision>
  </link>
  <joint
    name="base_imu_joint"
    type="fixed">
    <origin
      xyz="0.14371 0 -0.058338"
      rpy="0 0 0" />
    <parent
      link="base" />
    <child
      link="base_imu" />
    <axis
      xyz="0 0 0" />
  </joint>
</robot>