<?xml version="1.0" encoding="utf-8"?>
<!-- This URDF was automatically created by SolidWorks to URDF Exporter! Originally created by Stephen Brawner (brawner@gmail.com) 
     Commit Version: 1.6.0-4-g7f85cfe  Build Version: 1.6.7995.38578
     For more information, please see http://wiki.ros.org/sw_urdf_exporter -->
<robot
  name="leg_urdf20250417_1">
  <link
    name="base">
    <inertial>
      <origin
        xyz="-0.0066699 -0.0036748 -0.0047946"
        rpy="0 0 0" />
      <mass
        value="5.3832" />
      <inertia
        ixx="0.013437"
        ixy="-6.9871E-06"
        ixz="-0.00020711"
        iyy="0.031665"
        iyz="-9.5328E-06"
        izz="0.039598" />
    </inertial>
    <visual>
      <origin
        xyz="0 0 0"
        rpy="0 0 0" />
      <geometry>
        <mesh
          filename="file:///$(find leg_urdf20250417_1)/meshes/base.STL" />
      </geometry>
      <material
        name="">
        <color
          rgba="0.25098 0.25098 0.25098 1" />
      </material>
    </visual>
    <collision>
      <origin
        xyz="0 0 0"
        rpy="0 0 0" />
      <geometry>
        <mesh
          filename="file:///$(find leg_urdf20250417_1)/meshes/base.STL" />
      </geometry>
    </collision>
  </link>
  <link
    name="LF_hip">
    <inertial>
      <origin
        xyz="0.042864 -0.00047394 -2.8926E-05"
        rpy="0 0 0" />
      <mass
        value="0.16386" />
      <inertia
        ixx="0.00012341"
        ixy="-5.2157E-06"
        ixz="-1.1555E-06"
        iyy="0.0001958"
        iyz="-9.8907E-08"
        izz="0.00010494" />
    </inertial>
    <visual>
      <origin
        xyz="0 0 0"
        rpy="0 0 0" />
      <geometry>
        <mesh
          filename="file:///$(find leg_urdf20250417_1)/meshes/LF_hip.STL" />
      </geometry>
      <material
        name="">
        <color
          rgba="0.89804 0.91765 0.92941 1" />
      </material>
    </visual>
    <collision>
      <origin
        xyz="0 0 0"
        rpy="0 0 0" />
      <geometry>
        <mesh
          filename="file:///$(find leg_urdf20250417_1)/meshes/LF_hip.STL" />
      </geometry>
    </collision>
  </link>
  <joint
    name="LF_HAA"
    type="revolute">
    <origin
      xyz="0.1978 0.06 -0.0073383"
      rpy="0 0 0" />
    <parent
      link="base" />
    <child
      link="LF_hip" />
    <axis
      xyz="1 0 0" />
    <!-- 忽略这两个link之间的碰撞检测 -->
    <disable_collisions>true</disable_collisions>  
    <dynamics damping="0" friction="0"/>    
    <limit
      lower="-1.05"
      upper="1.05"
      effort="60"
      velocity="15" />
  </joint>
  <link
    name="LF_thigh">
    <inertial>
      <origin
        xyz="0.00436683720793923 0.0220762223078676 -0.094095264106613"
        rpy="0 0 0" />
      <mass
        value="0.88264952697142" />
      <inertia
        ixx="0.00415924322538449"
        ixy="-5.34750962434055E-06"
        ixz="-9.05829574075116E-05"
        iyy="0.00457431590966923"
        iyz="3.5094545931096E-05"
        izz="0.000520630016824553" />
    </inertial>
    <visual>
      <origin
        xyz="0 0 0"
        rpy="0 0 0" />
      <geometry>
        <mesh
          filename="file:///$(find leg_urdf20250417_1)/meshes/LF_thigh.STL" />
      </geometry>
      <material
        name="">
        <color
          rgba="0.898039215686275 0.917647058823529 0.929411764705882 1" />
      </material>
    </visual>
    <collision>
      <origin
        xyz="0 0 0"
        rpy="0 0 0" />
      <geometry>
        <mesh
          filename="file:///$(find leg_urdf20250417_1)/meshes/LF_thigh.STL" />
      </geometry>
    </collision>
  </link>
  <joint
    name="LF_HFE"
    type="revolute">
    <origin
      xyz="0.0627 0.0624 0"
      rpy="0 1 0" />
    <parent
      link="LF_hip" />
    <child
      link="LF_thigh" />
    <axis
      xyz="0 1 0" />
    <!-- 忽略这两个link之间的碰撞检测 -->
    <disable_collisions>true</disable_collisions> 
    <dynamics damping="0" friction="0"/>     
    <limit
      lower="-1.57"
      upper="3.35"
      effort="60"
      velocity="15" />
  </joint>
  <link
    name="LF_calf">
    <inertial>
      <origin
        xyz="0.0353231393749997 0.000329711873662181 0.137279161740425"
        rpy="0 0 0" />
      <mass
        value="0.291228893559729" />
      <inertia
        ixx="0.00107142137463083"
        ixy="8.16218987771122E-08"
        ixz="-0.000225822383336276"
        iyy="0.0011429950874814"
        iyz="1.42384757266927E-07"
        izz="8.3967835261648E-05" />
    </inertial>
    <visual>
      <origin
        xyz="0 0 0"
        rpy="0 0 0" />
      <geometry>
        <mesh
          filename="file:///$(find leg_urdf20250417_1)/meshes/LF_calf.STL" />
      </geometry>
      <material
        name="">
        <color
          rgba="1 1 1 1" />
      </material>
    </visual>
    <collision>
      <origin
        xyz="0 0 0"
        rpy="0 0 0" />
      <geometry>
        <mesh
          filename="file:///$(find leg_urdf20250417_1)/meshes/LF_calf.STL" />
      </geometry>
    </collision>
  </link>
  <joint
    name="LF_KFE"
    type="revolute">
    <origin
      xyz="0.024642 0.033 -0.28146"
      rpy="0 0 0" />
    <parent
      link="LF_thigh" />
    <child
      link="LF_calf" />
    <axis
      xyz="0 1 0" />
    <!-- 忽略这两个link之间的碰撞检测 -->
    <disable_collisions>true</disable_collisions>  
    <dynamics damping="0" friction="0"/>    
    <limit
      lower="0"
      upper="2.2"
      effort="60"
      velocity="15" />
  </joint>
  <link
    name="LF_FOOT">
    <inertial>
      <origin
        xyz="-0.00205174704649136 5.72936612042163E-09 -0.0079948269272665"
        rpy="0 0 0" />
      <mass
        value="0.0259775757821095" />
      <inertia
        ixx="2.79592928416496E-06"
        ixy="-1.63313531925429E-12"
        ixz="1.34865618051156E-06"
        iyy="6.06492352296267E-06"
        iyz="-1.56243203041687E-12"
        izz="5.00319213757495E-06" />
    </inertial>
    <visual>
      <origin
        xyz="0 0 0"
        rpy="0 0 0" />
      <geometry>
        <mesh
          filename="file:///$(find leg_urdf20250417_1)/meshes/LF_FOOT.STL" />
      </geometry>
      <material
        name="">
        <color
          rgba="0.384313725490196 0.384313725490196 0.384313725490196 1" />
      </material>
    </visual>
    <collision>
      <origin
        xyz="0 0 0"
        rpy="0 0 0" />
      <geometry>
        <mesh
          filename="file:///$(find leg_urdf20250417_1)/meshes/LF_FOOT.STL" />
      </geometry>
    </collision>
  </link>
  <joint
    name="LF_foot_fixed"
    type="fixed">
    <origin
      xyz="0.0789 0.0003 0.28158"
      rpy="0 0 0" />
    <parent
      link="LF_calf" />
    <child
      link="LF_FOOT" />
    <!-- 忽略这两个link之间的碰撞检测 -->
    <disable_collisions>true</disable_collisions>   
    <dynamics damping="0" friction="0"/>   
  </joint>
  <link
    name="LH_hip">
    <inertial>
      <origin
        xyz="-0.0433644646355627 -0.000473926080253484 2.89141840376095E-05"
        rpy="0 0 0" />
      <mass
        value="0.163855342532759" />
      <inertia
        ixx="0.000123407065872472"
        ixy="5.21572443527369E-06"
        ixz="-1.15546077566524E-06"
        iyy="0.000195800284944935"
        iyz="9.8908641921908E-08"
        izz="0.000104939607046793" />
    </inertial>
    <visual>
      <origin
        xyz="0 0 0"
        rpy="0 0 0" />
      <geometry>
        <mesh
          filename="file:///$(find leg_urdf20250417_1)/meshes/LH_hip.STL" />
      </geometry>
      <material
        name="">
        <color
          rgba="0.898039215686275 0.917647058823529 0.929411764705882 1" />
      </material>
    </visual>
    <collision>
      <origin
        xyz="0 0 0"
        rpy="0 0 0" />
      <geometry>
        <mesh
          filename="file:///$(find leg_urdf20250417_1)/meshes/LH_hip.STL" />
      </geometry>
    </collision>
  </link>
  <joint
    name="LH_HAA"
    type="revolute">
    <origin
      xyz="-0.1973 0.06 -0.0073383"
      rpy="0 0 0" />
    <parent
      link="base" />
    <child
      link="LH_hip" />
    <axis
      xyz="-1 0 0" />
    <!-- 忽略这两个link之间的碰撞检测 -->
    <disable_collisions>true</disable_collisions>  
    <dynamics damping="0" friction="0"/>   
    <limit
      lower="-1.05"
      upper="1.05"
      effort="60"
      velocity="15" />
  </joint>
  <link
    name="LH_thigh">
    <inertial>
      <origin
        xyz="0.00698096519153829 0.0650895843741195 -0.0944113598442908"
        rpy="0 0 0" />
      <mass
        value="0.878447187632765" />
      <inertia
        ixx="0.00416750965447208"
        ixy="-5.43183756066054E-06"
        ixz="-0.000180808380847781"
        iyy="0.00457417201818827"
        iyz="3.50847647011872E-05"
        izz="0.000512190640093904" />
    </inertial>
    <visual>
      <origin
        xyz="0 0 0"
        rpy="0 0 0" />
      <geometry>
        <mesh
          filename="file:///$(find leg_urdf20250417_1)/meshes/LH_thigh.STL" />
      </geometry>
      <material
        name="">
        <color
          rgba="0.898039215686275 0.917647058823529 0.929411764705882 1" />
      </material>
    </visual>
    <collision>
      <origin
        xyz="0 0 0"
        rpy="0 0 0" />
      <geometry>
        <mesh
          filename="file:///$(find leg_urdf20250417_1)/meshes/LH_thigh.STL" />
      </geometry>
    </collision>
  </link>
  <joint
    name="LH_HFE"
    type="revolute">
    <origin
      xyz="-0.0632 0.0195 0"
      rpy="0 1 0" />
    <parent
      link="LH_hip" />
    <child
      link="LH_thigh" />
    <axis
      xyz="0 1 0" />
    <!-- 忽略这两个link之间的碰撞检测 -->
    <disable_collisions>true</disable_collisions>
    <dynamics damping="0" friction="0"/>      
    <limit
      lower="-1.57"
      upper="3.35"
      effort="60"
      velocity="15" />
  </joint>
  <link
    name="LH_calf">
    <inertial>
      <origin
        xyz="0.0353231333049272 0.000329711201311145 0.137279155556145"
        rpy="0 0 0" />
      <mass
        value="0.291228914633656" />
      <inertia
        ixx="0.00107142137803892"
        ixy="8.16206824433646E-08"
        ixz="-0.000225822385994408"
        iyy="0.00114299509724133"
        iyz="1.42384066204264E-07"
        izz="8.39678418973689E-05" />
    </inertial>
    <visual>
      <origin
        xyz="0 0 0"
        rpy="0 0 0" />
      <geometry>
        <mesh
          filename="file:///$(find leg_urdf20250417_1)/meshes/LH_calf.STL" />
      </geometry>
      <material
        name="">
        <color
          rgba="1 1 1 1" />
      </material>
    </visual>
    <collision>
      <origin
        xyz="0 0 0"
        rpy="0 0 0" />
      <geometry>
        <mesh
          filename="file:///$(find leg_urdf20250417_1)/meshes/LH_calf.STL" />
      </geometry>
    </collision>
  </link>
  <joint
    name="LH_KFE"
    type="revolute">
    <origin
      xyz="0.025437 0.0759 -0.28147"
      rpy="0 0 0" />
    <parent
      link="LH_thigh" />
    <child
      link="LH_calf" />
    <axis
      xyz="0 1 0" />
    <!-- 忽略这两个link之间的碰撞检测 -->
    <disable_collisions>true</disable_collisions>      
    <dynamics damping="0" friction="0"/>
    <limit
      lower="0"
      upper="2.2"
      effort="60"
      velocity="15" />
  </joint>
  <link
    name="LH_FOOT">
    <inertial>
      <origin
        xyz="-0.00205174704649144 5.72936628695508E-09 -0.00799482692726639"
        rpy="0 0 0" />
      <mass
        value="0.0259775757821096" />
      <inertia
        ixx="2.79592928416496E-06"
        ixy="-1.6331353904199E-12"
        ixz="1.34865618051155E-06"
        iyy="6.06492352296266E-06"
        iyz="-1.56243197839901E-12"
        izz="5.00319213757494E-06" />
    </inertial>
    <visual>
      <origin
        xyz="0 0 0"
        rpy="0 0 0" />
      <geometry>
        <mesh
          filename="file:///$(find leg_urdf20250417_1)/meshes/LH_FOOT.STL" />
      </geometry>
      <material
        name="">
        <color
          rgba="0.384313725490196 0.384313725490196 0.384313725490196 1" />
      </material>
    </visual>
    <collision>
      <origin
        xyz="0 0 0"
        rpy="0 0 0" />
      <geometry>
        <mesh
          filename="file:///$(find leg_urdf20250417_1)/meshes/LH_FOOT.STL" />
      </geometry>
    </collision>
  </link>
  <joint
    name="LH_foot_fixed"
    type="fixed">
    <origin
      xyz="0.0789 0.0003 0.28158"
      rpy="0 0 0" />
    <parent
      link="LH_calf" />
    <child
      link="LH_FOOT" />
    <!-- 忽略这两个link之间的碰撞检测 -->
    <disable_collisions>true</disable_collisions>
    <dynamics damping="0" friction="0"/>      
  </joint>
  <link
    name="RF_hip">
    <inertial>
      <origin
        xyz="0.0433644648693298 0.000473947962982287 -2.8921744416377E-05"
        rpy="0 0 0" />
      <mass
        value="0.163855386935685" />
      <inertia
        ixx="0.000123407074924426"
        ixy="5.21571674467526E-06"
        ixz="-1.15545094341875E-06"
        iyy="0.000195800300641504"
        iyz="9.89103694234539E-08"
        izz="0.000104939625038023" />
    </inertial>
    <visual>
      <origin
        xyz="0 0 0"
        rpy="0 0 0" />
      <geometry>
        <mesh
          filename="file:///$(find leg_urdf20250417_1)/meshes/RF_hip.STL" />
      </geometry>
      <material
        name="">
        <color
          rgba="0.898039215686275 0.917647058823529 0.929411764705882 1" />
      </material>
    </visual>
    <collision>
      <origin
        xyz="0 0 0"
        rpy="0 0 0" />
      <geometry>
        <mesh
          filename="file:///$(find leg_urdf20250417_1)/meshes/RF_hip.STL" />
      </geometry>
    </collision>
  </link>
  <joint
    name="RF_HAA"
    type="revolute">
    <origin
      xyz="0.1973 -0.06 -0.0073383"
      rpy="0 0 0" />
    <parent
      link="base" />
    <child
      link="RF_hip" />
    <axis
      xyz="1 0 0" />
    <!-- 忽略这两个link之间的碰撞检测 -->
    <disable_collisions>true</disable_collisions> 
    <dynamics damping="0" friction="0"/>     
    <limit
      lower="-1.05"
      upper="1.05"
      effort="60"
      velocity="15" />
  </joint>
  <link
    name="RF_thigh">
    <inertial>
      <origin
        xyz="0.00450532741981957 -0.0651233509730109 -0.0943309028284361"
        rpy="0 0 0" />
      <mass
        value="0.880353408720974" />
      <inertia
        ixx="0.00415842883045723"
        ixy="5.34875598523861E-06"
        ixz="-9.05011725768454E-05"
        iyy="0.0045734761437616"
        iyz="-3.50630935382064E-05"
        izz="0.000520561613293803" />
    </inertial>
    <visual>
      <origin
        xyz="0 0 0"
        rpy="0 0 0" />
      <geometry>
        <mesh
          filename="file:///$(find leg_urdf20250417_1)/meshes/RF_thigh.STL" />
      </geometry>
      <material
        name="">
        <color
          rgba="0.898039215686275 0.917647058823529 0.929411764705882 1" />
      </material>
    </visual>
    <collision>
      <origin
        xyz="0 0 0"
        rpy="0 0 0" />
      <geometry>
        <mesh
          filename="file:///$(find leg_urdf20250417_1)/meshes/RF_thigh.STL" />
      </geometry>
    </collision>
  </link>
  <joint
    name="RF_HFE"
    type="revolute">
    <origin
      xyz="0.0632 -0.0195 0"
      rpy="0 1 0" />
    <parent
      link="RF_hip" />
    <child
      link="RF_thigh" />
    <axis
      xyz="0 -1 0" />
    <!-- 忽略这两个link之间的碰撞检测 -->
    <disable_collisions>true</disable_collisions>
    <dynamics damping="0" friction="0"/>      
    <limit
      lower="-3.35"
      upper="1.57"
      effort="60"
      velocity="15" />
  </joint>
  <link
    name="RF_calf">
    <inertial>
      <origin
        xyz="0.0353226630049198 -0.000330081314130204 0.137276291361542"
        rpy="0 0 0" />
      <mass
        value="0.291237111817664" />
      <inertia
        ixx="0.00107148301804938"
        ixy="-8.25716094186912E-08"
        ixz="-0.000225830862552133"
        iyy="0.00114305842409935"
        iyz="-1.42952371989529E-07"
        izz="8.39698788065223E-05" />
    </inertial>
    <visual>
      <origin
        xyz="0 0 0"
        rpy="0 0 0" />
      <geometry>
        <mesh
          filename="file:///$(find leg_urdf20250417_1)/meshes/RF_calf.STL" />
      </geometry>
      <material
        name="">
        <color
          rgba="1 1 1 1" />
      </material>
    </visual>
    <collision>
      <origin
        xyz="0 0 0"
        rpy="0 0 0" />
      <geometry>
        <mesh
          filename="file:///$(find leg_urdf20250417_1)/meshes/RF_calf.STL" />
      </geometry>
    </collision>
  </link>
  <joint
    name="RF_KFE"
    type="revolute">
    <origin
      xyz="0.024642 -0.0759 -0.28146"
      rpy="0 0 0" />
    <parent
      link="RF_thigh" />
    <child
      link="RF_calf" />
    <axis
      xyz="0 -1 0" />
    <!-- 忽略这两个link之间的碰撞检测 -->
    <disable_collisions>true</disable_collisions>
    <dynamics damping="0" friction="0"/>      
    <limit
      lower="-2.2"
      upper="0"
      effort="60"
      velocity="15" />
  </joint>
  <link
    name="RF_FOOT">
    <inertial>
      <origin
        xyz="-0.00205181667049559 2.37805291014581E-08 -0.00799478854830682"
        rpy="0 0 0" />
      <mass
        value="0.0259777190681024" />
      <inertia
        ixx="2.79593674615042E-06"
        ixy="-4.46950623717648E-12"
        ixz="1.34866647099014E-06"
        iyy="6.06496341868077E-06"
        iyz="-4.02748106747732E-12"
        izz="5.00322920227979E-06" />
    </inertial>
    <visual>
      <origin
        xyz="0 0 0"
        rpy="0 0 0" />
      <geometry>
        <mesh
          filename="file:///$(find leg_urdf20250417_1)/meshes/RF_FOOT.STL" />
      </geometry>
      <material
        name="">
        <color
          rgba="0.384313725490196 0.384313725490196 0.384313725490196 1" />
      </material>
    </visual>
    <collision>
      <origin
        xyz="0 0 0"
        rpy="0 0 0" />
      <geometry>
        <mesh
          filename="file:///$(find leg_urdf20250417_1)/meshes/RF_FOOT.STL" />
      </geometry>
    </collision>
  </link>
  <joint
    name="RF_foot_fixed"
    type="fixed">
    <origin
      xyz="0.0789 -0.0003 0.28158"
      rpy="0 0 0" />
    <parent
      link="RF_calf" />
    <child
      link="RF_FOOT" />
    <!-- 忽略这两个link之间的碰撞检测 -->
    <disable_collisions>true</disable_collisions> 
    <dynamics damping="0" friction="0"/>     
  </joint>
  <link
    name="RH_hip">
    <inertial>
      <origin
        xyz="-0.0249543538828536 0.000473931035222447 2.89098388941422E-05"
        rpy="0 0 0" />
      <mass
        value="0.163855386935684" />
      <inertia
        ixx="0.000123407074916225"
        ixy="-5.21572449374408E-06"
        ixz="-1.15545638126958E-06"
        iyy="0.000195800305834429"
        iyz="-9.89121708491203E-08"
        izz="0.000104939619828281" />
    </inertial>
    <visual>
      <origin
        xyz="0 0 0"
        rpy="0 0 0" />
      <geometry>
        <mesh
          filename="file:///$(find leg_urdf20250417_1)/meshes/RH_hip.STL" />
      </geometry>
      <material
        name="">
        <color
          rgba="0.792156862745098 0.819607843137255 0.933333333333333 1" />
      </material>
    </visual>
    <collision>
      <origin
        xyz="0 0 0"
        rpy="0 0 0" />
      <geometry>
        <mesh
          filename="file:///$(find leg_urdf20250417_1)/meshes/RH_hip.STL" />
      </geometry>
    </collision>
  </link>
  <joint
    name="RH_HAA"
    type="revolute">
    <origin
      xyz="-0.21571 -0.06 -0.0073383"
      rpy="0 0 0" />
    <parent
      link="base" />
    <child
      link="RH_hip" />
    <axis
      xyz="-1 0 0" />
    <!-- 忽略这两个link之间的碰撞检测 -->
    <disable_collisions>true</disable_collisions>
    <dynamics damping="0" friction="0"/>      
    <limit
      lower="-1.05"
      upper="1.05"
      effort="60"
      velocity="15" />
  </joint>
  <link
    name="RH_thigh">
    <inertial>
      <origin
        xyz="0.00710534632870674 -0.0466324522810538 -0.0962519270351891"
        rpy="0 0 0" />
      <mass
        value="0.882603587739274" />
      <inertia
        ixx="0.00416688393002433"
        ixy="5.43276009424337E-06"
        ixz="-0.000180728703304211"
        iyy="0.00457356125280747"
        iyz="-3.50534981577596E-05"
        izz="0.000512221191717673" />
    </inertial>
    <visual>
      <origin
        xyz="0 0 0"
        rpy="0 0 0" />
      <geometry>
        <mesh
          filename="file:///$(find leg_urdf20250417_1)/meshes/RH_thigh.STL" />
      </geometry>
      <material
        name="">
        <color
          rgba="0.898039215686275 0.917647058823529 0.929411764705882 1" />
      </material>
    </visual>
    <collision>
      <origin
        xyz="0 0 0"
        rpy="0 0 0" />
      <geometry>
        <mesh
          filename="file:///$(find leg_urdf20250417_1)/meshes/RH_thigh.STL" />
      </geometry>
    </collision>
  </link>
  <joint
    name="RH_HFE"
    type="revolute">
    <origin
      xyz="-0.04479 -0.037843 0.0022486"
      rpy="0 1 0" />
    <parent
      link="RH_hip" />
    <child
      link="RH_thigh" />
    <axis
      xyz="0 -1 0" />
    <!-- 忽略这两个link之间的碰撞检测 -->
    <disable_collisions>true</disable_collisions> 
    <dynamics damping="0" friction="0"/>     
    <limit
      lower="-3.35"
      upper="1.57"
      effort="60"
      velocity="15" />
  </joint>
  <link
    name="RH_calf">
    <inertial>
      <origin
        xyz="0.0353226615807363 -0.000330086244457906 0.137276295276581"
        rpy="0 0 0" />
      <mass
        value="0.291237106817581" />
      <inertia
        ixx="0.00107148305889599"
        ixy="-8.25724052426126E-08"
        ixz="-0.000225830868100513"
        iyy="0.0011430584628429"
        iyz="-1.42954970137402E-07"
        izz="8.39698769396023E-05" />
    </inertial>
    <visual>
      <origin
        xyz="0 0 0"
        rpy="0 0 0" />
      <geometry>
        <mesh
          filename="file:///$(find leg_urdf20250417_1)/meshes/RH_calf.STL" />
      </geometry>
      <material
        name="">
        <color
          rgba="1 1 1 1" />
      </material>
    </visual>
    <collision>
      <origin
        xyz="0 0 0"
        rpy="0 0 0" />
      <geometry>
        <mesh
          filename="file:///$(find leg_urdf20250417_1)/meshes/RH_calf.STL" />
      </geometry>
    </collision>
  </link>
  <joint
    name="RH_KFE"
    type="revolute">
    <origin
      xyz="0.025437 -0.057557 -0.28372"
      rpy="0 0 0" />
    <parent
      link="RH_thigh" />
    <child
      link="RH_calf" />
    <axis
      xyz="0 -1 0" />
    <!-- 忽略这两个link之间的碰撞检测 -->
    <disable_collisions>true</disable_collisions>
    <dynamics damping="0" friction="0"/>      
    <limit
      lower="-2.2"
      upper="0"
      effort="60"
      velocity="15" />
  </joint>
  <link
    name="RH_FOOT">
    <inertial>
      <origin
        xyz="-0.00205181667049559 2.37805288516579E-08 -0.00799478854830671"
        rpy="0 0 0" />
      <mass
        value="0.025977719068102" />
      <inertia
        ixx="2.79593674615039E-06"
        ixy="-4.46950620699933E-12"
        ixz="1.34866647099013E-06"
        iyy="6.06496341868069E-06"
        iyz="-4.02748110374564E-12"
        izz="5.00322920227976E-06" />
    </inertial>
    <visual>
      <origin
        xyz="0 0 0"
        rpy="0 0 0" />
      <geometry>
        <mesh
          filename="file:///$(find leg_urdf20250417_1)/meshes/RH_FOOT.STL" />
      </geometry>
      <material
        name="">
        <color
          rgba="0.384313725490196 0.384313725490196 0.384313725490196 1" />
      </material>
    </visual>
    <collision>
      <origin
        xyz="0 0 0"
        rpy="0 0 0" />
      <geometry>
        <mesh
          filename="file:///$(find leg_urdf20250417_1)/meshes/RH_FOOT.STL" />
      </geometry>
    </collision>
  </link>
  <joint
    name="RH_foot_fixed"
    type="fixed">
    <origin
      xyz="0.0789 -0.00030001 0.28158"
      rpy="0 0 0" />
    <parent
      link="RH_calf" />
    <child
      link="RH_FOOT" />
    <!-- 忽略这两个link之间的碰撞检测 -->
    <disable_collisions>true</disable_collisions>    
    <dynamics damping="0" friction="0"/>  
  </joint>
</robot>